<?xml version="1.0" encoding="UTF-8"?>
<testng-results skipped="0" failed="1" ignored="0" total="1" passed="0">
  <reporter-output>
  </reporter-output>
  <suite name="Default suite" duration-ms="184" started-at="2022-07-07T22:37:55 IST" finished-at="2022-07-07T22:37:55 IST">
    <groups>
    </groups>
    <test name="Default test" duration-ms="184" started-at="2022-07-07T22:37:55 IST" finished-at="2022-07-07T22:37:55 IST">
      <class name="Project_adactin.Expected_exception">
        <test-method status="FAIL" signature="arithmatic_operation()[pri:0, instance:Project_adactin.Expected_exception@86be70a]" name="arithmatic_operation" duration-ms="13" started-at="2022-07-07T22:37:55 IST" finished-at="2022-07-07T22:37:55 IST">
          <exception class="org.testng.TestException">
            <message>
              <![CDATA[
Method Expected_exception.arithmatic_operation()[pri:0, instance:Project_adactin.Expected_exception@86be70a] should have thrown an exception of type class java.lang.ArithmeticException]]>
            </message>
            <full-stacktrace>
              <![CDATA[org.testng.TestException: 
Method Expected_exception.arithmatic_operation()[pri:0, instance:Project_adactin.Expected_exception@86be70a] should have thrown an exception of type class java.lang.ArithmeticException
at org.testng.internal.ExpectedExceptionsHolder.noException(ExpectedExceptionsHolder.java:82)
at org.testng.internal.TestInvoker.considerExceptions(TestInvoker.java:749)
at org.testng.internal.TestInvoker.invokeMethod(TestInvoker.java:634)
at org.testng.internal.TestInvoker.invokeTestMethod(TestInvoker.java:173)
at org.testng.internal.MethodRunner.runInSequence(MethodRunner.java:46)
at org.testng.internal.TestInvoker$MethodInvocationAgent.invoke(TestInvoker.java:824)
at org.testng.internal.TestInvoker.invokeTestMethods(TestInvoker.java:146)
at org.testng.internal.TestMethodWorker.invokeTestMethods(TestMethodWorker.java:146)
at org.testng.internal.TestMethodWorker.run(TestMethodWorker.java:128)
at java.util.ArrayList.forEach(Unknown Source)
at org.testng.TestRunner.privateRun(TestRunner.java:794)
at org.testng.TestRunner.run(TestRunner.java:596)
at org.testng.SuiteRunner.runTest(SuiteRunner.java:377)
at org.testng.SuiteRunner.runSequentially(SuiteRunner.java:371)
at org.testng.SuiteRunner.privateRun(SuiteRunner.java:332)
at org.testng.SuiteRunner.run(SuiteRunner.java:276)
at org.testng.SuiteRunnerWorker.runSuite(SuiteRunnerWorker.java:53)
at org.testng.SuiteRunnerWorker.run(SuiteRunnerWorker.java:96)
at org.testng.TestNG.runSuitesSequentially(TestNG.java:1212)
at org.testng.TestNG.runSuitesLocally(TestNG.java:1134)
at org.testng.TestNG.runSuites(TestNG.java:1063)
at org.testng.TestNG.run(TestNG.java:1031)
at org.testng.remote.AbstractRemoteTestNG.run(AbstractRemoteTestNG.java:115)
at org.testng.remote.RemoteTestNG.initAndRun(RemoteTestNG.java:251)
at org.testng.remote.RemoteTestNG.main(RemoteTestNG.java:77)
]]>
            </full-stacktrace>
          </exception> <!-- org.testng.TestException -->
          <reporter-output>
          </reporter-output>
        </test-method> <!-- arithmatic_operation -->
      </class> <!-- Project_adactin.Expected_exception -->
    </test> <!-- Default test -->
  </suite> <!-- Default suite -->
</testng-results>
